<?xml version="1.0" encoding="utf-8"?>

<robot name="xavier_car" xmlns:xacro="http://ros.org/wiki/xacro">

  <xacro:include filename="$(find robot_description)/urdf/xavier_car/macros.xacro" />

  <link name="base_footprint">
  </link>
  
  <!-- Joint 1 -->


  <link name="base_link">
    <inertial>
      <origin xyz="0 0 0" />
      <mass value="4" />
      <inertia ixx="0.0264" ixy="0" ixz="0" iyy="0.0294" iyz="0" izz="0.00364" />
    </inertial>
    <visual>
      <origin xyz="0 0 0" rpy="0 0 0" />
      <geometry>
      <mesh filename="package://robot_description/meshes/xavier_car/base_link.STL" />
      </geometry>
      <material name="">
      <color rgba="0 0.62745 0.23529 1" />
      </material>
    </visual>
    <collision>
      <origin xyz="0 0 0" rpy="0 0 0" />
      <geometry>
        <mesh filename="package://robot_description/meshes/xavier_car/base_link.STL" />
      </geometry>
    </collision>
  </link>


  <joint name="base_link2base_footprint" type="fixed">
    <parent link="base_footprint"/>
    <child link="base_link"/>
    <origin xyz="0 0 0" rpy="0 0 0"/>
  </joint>

  <!-- Adding base_inertia and its joint -->


  <gazebo reference="base_link">
    <material>Gazebo/Red</material>
  </gazebo>

  <link name="back_right_link">
    <inertial>
      <origin xyz="0 0 0" />
      <mass value="2.0" />
      <inertia ixx="6.64E-04" ixy="0" ixz="0" iyy="6.64E-04" iyz="0" izz="1.02E-03" />
    </inertial>
    <visual>
      <origin xyz="0 0 0" rpy="0 0 0" />
      <geometry>
      <mesh filename="package://robot_description/meshes/xavier_car/back_right_link.STL" />
      </geometry>
      <material name="">
      <color rgba="0.79216 0.81961 0.93333 1" />
      </material>
    </visual>
    <collision>
      <origin xyz="0 0 0" rpy="0 0 0" />
      <geometry>
        <mesh filename="package://robot_description/meshes/xavier_car/back_right_link.STL" />
      </geometry>
      <surface>
        <friction>
          <ode>
            <mu>0.01</mu>
            <mu2>0.01</mu2>
          </ode>
        </friction>
      </surface>
    </collision>
  </link>
  
  <gazebo reference="back_right_link">
    <material>Gazebo/Black</material>
  </gazebo>

  <!-- Joint 2 -->
  <joint name="back_right_joint" type="continuous">
    <origin xyz="-0.13 -0.09 0" />
    <parent link="base_link" />
    <child link="back_right_link" />
    <axis xyz="0 1 0" />
    <limit effort="10" velocity="1000" />
  </joint>
  <xacro:wheel_transmission name="back_right" />

  <link name="back_left_link">
    <inertial>
      <origin xyz="0 0 0" />
      <mass value="2.0" />
      <inertia ixx="6.64E-04" ixy="0" ixz="0" iyy="6.64E-04" iyz="0" izz="1.02E-03" />
    </inertial>
    <visual>
      <origin xyz="0 0 0" rpy="0 0 0" />
      <geometry>
      <mesh filename="package://robot_description/meshes/xavier_car/back_right_link.STL" />
      </geometry>
      <material name="">
      <color rgba="0.792156862745098 0.819607843137255 0.933333333333333 1" />
      </material>
    </visual>
    <collision>
      <origin xyz="0 0 0" rpy="0 0 0" />
      <geometry>
        <mesh filename="package://robot_description/meshes/xavier_car/back_right_link.STL" />
      </geometry>
      <surface>
        <friction>
          <ode>
            <mu>0.01</mu>
            <mu2>0.01</mu2>
          </ode>
        </friction>
      </surface>
    </collision>
  </link>

  <gazebo reference="back_left_link">
    <material>Gazebo/Black</material>
  </gazebo>
  
  <!-- Joint 3 -->
  <joint name="back_left_joint" type="continuous">
    <origin xyz="-0.13 0.09 0" />
    <parent link="base_link" />
    <child link="back_left_link" />
    <axis xyz="0 1 0" />
    <limit effort="10" velocity="1000" />
  </joint>
  <xacro:wheel_transmission name="back_left" />

  <link name="front_left_steer">
    <inertial>
      <origin xyz="0 0 0" rpy="0 0 0" />
      <mass value="0.5" />
      <inertia ixx="1.35E-05" ixy="0" ixz="0" iyy="1.35E-05" iyz="0" izz="2.5E-05" />
    </inertial>
    <visual>
      <origin xyz="0 0 0" rpy="0 0 0" />
      <geometry>
      <mesh filename="package://robot_description/meshes/xavier_car/front_left_steer.STL" />
      </geometry>
      <material name="">
      <color rgba="0.082353 0.56078 0 1" />
      </material>
    </visual>
    <collision>
      <origin xyz="0 0 0" rpy="0 0 0" />
      <geometry>
        <mesh filename="package://robot_description/meshes/xavier_car/front_left_steer.STL" />
      </geometry>
    </collision>
  </link>
  
  <!-- Joint 4 -->
  <joint name="front_left_steer_joint" type="revolute">
    <origin xyz="0.13 0.065 0" />
    <parent link="base_link" />
    <child link="front_left_steer" />
    <axis xyz="0 0 1" />
    <limit lower="-0.6" upper="0.6" effort="5.0" velocity="1000.0" />
  </joint>
  <xacro:steering_hinge_transmission name="front_left_steer" />

  <link name="front_left_wheel">
    <inertial>
      <origin xyz="0 0 0" />
      <mass value="2.0" />
      <inertia ixx="6.64E-04" ixy="0" ixz="0" iyy="6.64E-04" iyz="0" izz="1.02E-03" />
    </inertial>
    <visual>
        <origin xyz="0 0 0" rpy="0 0 0" />
        <geometry>
        <mesh filename="package://robot_description/meshes/xavier_car/back_right_link.STL" />
        </geometry>
        <material name="">
        <color rgba="0.79216 0.81961 0.93333 1" />
        </material>
      
    </visual>
    <collision>
     <origin xyz="0 0 0" rpy="0 0 0" />
      <geometry>
        <mesh filename="package://robot_description/meshes/xavier_car/back_right_link.STL" />
      </geometry>
      <surface>
        <friction>
          <ode>
            <mu>0.01</mu>
            <mu2>0.01</mu2>
          </ode>
        </friction>
      </surface>
    </collision>
  </link>

  <gazebo reference="front_left_wheel">
    <material>Gazebo/Black</material>
  </gazebo>
  
  <!-- Joint 5 -->
  <joint name="front_left_wheel_joint" type="continuous">
    <origin xyz="0 0.025 0" />
    <parent link="front_left_steer" />
    <child link="front_left_wheel" />
    <axis xyz="0 1 0" />
    <limit effort="10" velocity="1000" />
  </joint>
  <xacro:wheel_transmission name="front_left_wheel" />

  <link name="front_right_steer">
    <inertial>
      <origin xyz="0 0 0" />
      <mass value="0.5" />
      <inertia ixx="1.35E-05" ixy="0" ixz="0" iyy="1.35E-05" iyz="0" izz="2.5E-05" />
    </inertial>
    <visual>
      <origin xyz="0 0 0" rpy="0 0 0" />
      <geometry>
      <mesh filename="package://robot_description/meshes/xavier_car/front_left_steer.STL" />
      </geometry>
      <material name="">
      <color rgba="0.082353 0.56078 0 1" />
      </material>
    </visual>
    <collision>
      <origin xyz="0 0 0" rpy="0 0 0" />
      <geometry>
        <mesh filename="package://robot_description/meshes/xavier_car/front_left_steer.STL" />
      </geometry>
    </collision>
  </link>
  
  <!-- Joint 6 -->
  <joint name="front_right_steer_joint" type="revolute">
    <origin xyz="0.13 -0.065 0" />
    <parent link="base_link" />
    <child link="front_right_steer" />
    <axis xyz="0 0 1" />
    <limit lower="-0.6" upper="0.6" effort="5.0" velocity="1000.0"/>
  </joint>
  <xacro:steering_hinge_transmission name="front_right_steer" />

  <link name="front_right_wheel">
    <inertial>
      <origin xyz="0 0 0" />
      <mass value="2.0" />
      <inertia ixx="6.64E-04" ixy="0" ixz="0" iyy="6.64E-04" iyz="0" izz="1.02E-03" />
    </inertial>
    <visual>
      <origin xyz="0 0 0" rpy="0 0 0" />
      <geometry>
      <mesh filename="package://robot_description/meshes/xavier_car/back_right_link.STL" />
      </geometry>
      <material name="">
      <color rgba="0.79216 0.81961 0.93333 1" />
      </material>
     
    </visual>
    <collision>
      <origin xyz="0 0 0" rpy="0 0 0" />
      <geometry>
        <mesh filename="package://robot_description/meshes/xavier_car/back_right_link.STL" />
      </geometry>
      <surface>
        <friction>
          <ode>
            <mu>0.01</mu>
            <mu2>0.01</mu2>
          </ode>
        </friction>
      </surface>
    </collision>
  </link>
  
  <gazebo reference="front_right_wheel">
    <material>Gazebo/Black</material>
  </gazebo>
  
  <!-- Joint 7 -->
  <joint name="front_right_wheel_joint" type="continuous">
    <origin xyz="0 -0.025 0" />
    <parent link="front_right_steer" />
    <child link="front_right_wheel" />
    <axis xyz="0 1 0" />
    <limit effort="10" velocity="1000" />
  </joint>
  <xacro:wheel_transmission name="front_right_wheel" />

  <link name="camera">
    <inertial>
      <origin xyz="0 0 0" />
      <mass value="0.05" />
      <inertia ixx="6.64E-04" ixy="0" ixz="0" iyy="6.64E-04" iyz="0" izz="1.02E-03" />
    </inertial>
    <visual>
      <origin xyz="0 0 0" rpy="0 0 0" />
      <geometry>
      <mesh filename="package://robot_description/meshes/xavier_car/camera.STL" />
      </geometry>
      <material name="">
      <color rgba="0.082353 0.082353 0.082353 1" />
      </material>
    </visual>
    <collision>
      <origin xyz="0 0 0" rpy="0 0 0" />
      <geometry>
        <mesh filename="package://robot_description/meshes/xavier_car/camera.STL" />
      </geometry>
    </collision>
  </link>
  
  <gazebo reference="camera">
    <material>Gazebo/Black</material>
  </gazebo>
  
  <!-- Joint 8 -->
  <joint name="camera_joint" type="fixed">
    <origin xyz="0.14851 0.0022137 0.0975" />
    <parent link="base_link" />
    <child link="camera" />
    <axis xyz="0 0 1" />
  </joint>

  <xacro:arg name="gpu" default="false"/>
  <xacro:property name="gpu" value="$(arg gpu)" />
  <xacro:include filename="$(find robot_description)/urdf/xavier_car/vlp.urdf.xacro"/>
  <xacro:VLP-16 parent="base_link" name="velodyne" topic="/velodyne_points" hz="40" samples="360" gpu="${gpu}">
    <origin xyz="-0.022 0 0.1" rpy="0 0 3.1416" />
  </xacro:VLP-16>


  <link name="imu">
    <inertial>
      <origin xyz="0 0 0" />
      <mass value="0.05" />
      <inertia ixx="6.64E-04" ixy="0" ixz="0" iyy="6.64E-04" iyz="0" izz="1.02E-03" />
    </inertial>
    <visual>
      <geometry>
        <box size="0.01 0.01 0.005"/>
      </geometry>
      <origin xyz="0 0 0" rpy="0 0 0" />
      <material name="black">
        <color rgba="0.0 0.0 0.0 1.0" />
      </material>
    </visual>
  </link>

  <!-- Joint 9 -->
  <joint name="base_imu" type="fixed">
    <parent link="base_link"/>
    <child link="imu"/>
    <origin xyz="-0.05 0.0 0.05" rpy="0 3.1415 1.5707"/>
  </joint>

 
<!--Gazebo file start-->

<xacro:include filename="$(find robot_description)/urdf/xavier_car/xavier_car.gazebo" />
   

</robot>
